Workbook

Sheet Products (2)
A1: Sku Number | B1: Theme | C1: Customer Description | D1: Sale Price | E1: Regular Price | F1: Specialty Brand | G1: Proprietary (P) | H1: Collection Copy | I1: Mattress Designation | J1: Mattress Size | K1: Mattress Type | L1: Pressure Relief | M1: Sleep Position | N1: Support Level | O1: Temperature Management | P1: Comfort
A2: 50000543 | B2: =_xlfn.XLOOKUP(A2,Sheet1!A:A,Sheet1!D:D,"") -> CASPER CLOUD ONE | C2: TWX CASPER CLOUD ONE | D2: =_xlfn.XLOOKUP(A2,Sheet1!A:A,Sheet1!C:C,"") -> 879 | E2: 1099 | F2: CASPER | I2: Adult | J2: Twin XL | K2: Foam | L2: 3-Superior | M2: Side/Back/Stomach | N2: 3-Superior | O2: 2-Good | P2: Medium
A3: 50000579 | B3: =_xlfn.XLOOKUP(A3,Sheet1!A:A,Sheet1!D:D,"") -> CASPER SNOW 2.0 | C3: TWXL CASPER SNOW 2.0 | D3: =_xlfn.XLOOKUP(A3,Sheet1!A:A,Sheet1!C:C,"") -> 1595 | E3: 1995 | F3: CASPER | H3: Casper signature cooling hybrid mattress. Specialty cool-to-the-touch fibers give an instantly refreshing feel. Phase Change Materialinstantly pulls heat away whileHeatDeleteT Bandsremove excess body heat to help yousleep 5 cooler all night long. Soothe Memory Foam conforms to the body and gently eases you into deep sleep. Zoned Support helps keep your spine in alignment with firmer foam under the hips, waist and lower back. Individually pocketed Flex Coils reduce motion transfer and boost support. | I3: Adult | J3: Twin XL | K3: Hybrid | L3: 3-Superior | M3: Side/Back/Stomach | N3: 3-Superior | O3: 4-Premier | P3: Medium
A4: 50000581 | B4: =_xlfn.XLOOKUP(A4,Sheet1!A:A,Sheet1!D:D,"") -> CASPER SNOW MAX | C4: TWXL CASPER SNOW MAX | D4: =_xlfn.XLOOKUP(A4,Sheet1!A:A,Sheet1!C:C,"") -> 2595 | E4: 3245 | F4: CASPER | H4: Ultimate cooling hybrid mattress. Specialty cool-to-the-touch fibers give an instantly refreshing feel. Phase Change MaterialandHeatDeleteT Bands remove excess body heat and help yousleep 6 cooler all night long. Precision-cut foam and encased coils for a breathable and supportive medium-soft feel. Ultra-supportive Align Memory Foam keeps you aligned for your deepest sleep. Firmer center foam cradles your body while giving added support to your hips, waist and lower back. Individually pocketed Flex Coils flex reduce motion transfer and boost support. | I4: Adult | J4: Twin XL | K4: Hybrid | L4: 4-Premier | M4: Side/Back | N4: 3-Superior | O4: 5-Ultimate | P4: Soft
A5: 50000682 | B5: =_xlfn.XLOOKUP(A5,Sheet1!A:A,Sheet1!D:D,"") -> CASPER ONYX 2.0 | C5: TWXL CASPER ONYX 2.0 | D5: =_xlfn.XLOOKUP(A5,Sheet1!A:A,Sheet1!C:C,"") -> 699 | E5: 799 | F5: CASPER | G5: P | H5: The Casper Onyx mattress is designed with 3 layers of foam for comfort, breathability and support. Obsessively engineered by Casper's award-winning research and development team, this mattress contains Breathe Flex Foam for support and pressure relief & Breathe Foam for air flow that pairs breathability with softness for all-night comfort. Key FeaturesA cozy knit cover designed with added stretch so you can experience all the comfort your mattress has to offer. Features a top layer of Breathe Flex Foam that's both responsive and breathable to soothe you to sleep with the perfect bit of bounce. A firm Casper Core base provides long-lasting support while preventing sinking and sagging. Foams are certified by the CertiPUR-US program, meaning they are made without ozone depleting chemicals and regulated by the Consumer Product Safety Commission Low VOC Volatile Organic Compound emissions for indoor air quality less than 0.5 parts per million. | I5: Adult | J5: Twin XL | K5: Foam | L5: 2-Good | M5: Side/Back/Stomach | N5: 2-Good | O5: 2-Good | P5: Medium
A6: 50001773 | B6: =_xlfn.XLOOKUP(A6,Sheet1!A:A,Sheet1!D:D,"") -> SMART MATCH 2.0 | C6: TWX SMART MATCH 2.0 | D6: =_xlfn.XLOOKUP(A6,Sheet1!A:A,Sheet1!C:C,"") -> 1077 | E6: 3199 | F6: KINGSDOWN | J6: Twin XL | K6: Innerspring | L6: 4-Premier | M6: Side/Back/Stomach | N6: 4-Premier | O6: 3-Superior | P6: Medium
A7: 50007460 | B7: =_xlfn.XLOOKUP(A7,Sheet1!A:A,Sheet1!D:D,"") -> ADAPT 2.0 MEDIUM | C7: TWXL ADAPT MEDIUM | D7: =_xlfn.XLOOKUP(A7,Sheet1!A:A,Sheet1!C:C,"") -> 1699 | E7: 1699 | F7: TEMPURPEDIC | H7: .Superior cool-to-the-touch feel with a premium knit cover..TEMPUR-Material provides one-of-a-kind, body-conforming support by responding to your body's weight, shape, and temperature to help reduce aches and pains..A second layer of TEMPUR-Material absorbs motion to help minimize disruptions caused by movement from partners, pets, or kids. | I7: Adult | J7: Twin XL | K7: Foam | L7: 4-Premier | M7: Side/Back/Stomach | N7: 4-Premier | O7: 4-Premier | P7: Medium
A8: 50007472 | B8: =_xlfn.XLOOKUP(A8,Sheet1!A:A,Sheet1!D:D,"") -> ADAPT 2.0 MEDIUM HYBRID | C8: TWXL ADAPT MEDIUM HYBRID | D8: =_xlfn.XLOOKUP(A8,Sheet1!A:A,Sheet1!C:C,"") -> 1999 | E8: 1999 | F8: TEMPURPEDIC | H8: .Superior cool-to-the-touch feel with a premium knit cover..TEMPUR-Material provides one-of-a-kind, body-conforming support by responding to your body's weight, shape, and temperature to help reduce aches and pains..A second layer of TEMPUR-Material absorbs motion to help minimize disruptions caused by movement from partners, pets, or kids..Hybrid technology combines premium innersprings with TEMPUR-Material to deliver the right combination of pressure relief and support. | I8: Adult | J8: Twin XL | K8: Hybrid | L8: 4-Premier | M8: Side/Back/Stomach | N8: 4-Premier | O8: 4-Premier | P8: Medium
A9: 50007484 | B9: =_xlfn.XLOOKUP(A9,Sheet1!A:A,Sheet1!D:D,"") -> PROADAPT 2.0 FIRM | C9: TWXL PROADAPT FIRM | D9: =_xlfn.XLOOKUP(A9,Sheet1!A:A,Sheet1!C:C,"") -> 2899 | E9: 2899 | F9: TEMPURPEDIC | H9: .The removable, machine-washable, and cool-to-the-touch SmartClimate cover features heat-absorbing fibers, drawing heat away from the body for added cooling comfort..Ventilated Advanced Relief Material provides pressure relief and added ventilation for increased airflow..TEMPUR-Material provides one-of-a-kind, body-conforming support by responding to your body's weight, shape, and temperature. | I9: Adult | J9: Twin XL | K9: Foam | L9: 4-Premier | M9: Stomach/Back | N9: 5-Ultimate | O9: 4-Premier | P9: Firm
A10: 50007511 | B10: =_xlfn.XLOOKUP(A10,Sheet1!A:A,Sheet1!D:D,"") -> PROBREEZE 2.0 MEDIUM HYBRID | C10: TWXL PROBREEZE MED HYBRID | D10: =_xlfn.XLOOKUP(A10,Sheet1!A:A,Sheet1!C:C,"") -> 3899 | E10: 3899 | F10: TEMPURPEDIC | H10: Experience all-night cooling with the all-new TEMPUR-ProBreeze mattress. Features a removable, machine-washable cover with heat-absorbing fibers that provide cooling comfort. Premium hybrid technology combines over 1,000 innersprings with Tempur-Pedic's pressure relieving and cooling materials. Delivers exceptional support and ensures cool and comfortable sleep every night. | I10: Adult | J10: Twin XL | K10: Hybrid | L10: 4-Premier | M10: Side/Back/Stomach | N10: 5-Ultimate | O10: 5-Ultimate | P10: Medium
A11: 50007523 | B11: =_xlfn.XLOOKUP(A11,Sheet1!A:A,Sheet1!D:D,"") -> PROADAPT 2.0 MEDIUM | C11: TWXL PROADAPT MEDIUM | D11: =_xlfn.XLOOKUP(A11,Sheet1!A:A,Sheet1!C:C,"") -> 2899 | E11: 2899 | F11: TEMPURPEDIC | H11: .The removable, machine-washable, and cool-to-the-touch SmartClimate cover features heat-absorbing fibers, drawing heat away from the body for added cooling comfort..Ventilated Advanced Relief Material provides pressure relief and added ventilation for increased airflow..TEMPUR-Material provides one-of-a-kind, body-conforming support by responding to your body's weight, shape, and temperature. | I11: Adult | J11: Twin XL | K11: Foam | L11: 4-Premier | M11: Side/Back/Stomach | N11: 5-Ultimate | O11: 4-Premier | P11: Medium
A12: 50007535 | B12: =_xlfn.XLOOKUP(A12,Sheet1!A:A,Sheet1!D:D,"") -> PROADAPT 2.0 SOFT | C12: TWXL PROADAPT SOFT | D12: =_xlfn.XLOOKUP(A12,Sheet1!A:A,Sheet1!C:C,"") -> 2899 | E12: 2899 | F12: TEMPURPEDIC | H12: .The removable, machine-washable, and cool-to-the-touch SmartClimate cover features heat-absorbing fibers, drawing heat away from the body for added cooling comfort..Specially ventilated TEMPUR-Material delivers additional airflow and breathability, while providing pressure relief and motion absorption..Advanced Relief Material is the most pressure-relieving material made by Tempur-Pedic and conforms to your body for ultimate comfort. | I12: Adult | J12: Twin XL | K12: Foam | L12: 5-Ultimate | M12: Side/Back | N12: 5-Ultimate | O12: 4-Premier | P12: Soft
A13: 50007559 | B13: =_xlfn.XLOOKUP(A13,Sheet1!A:A,Sheet1!D:D,"") -> PROADAPT 2.0 MEDIUM HYBRID | C13: TWXL PROADAPT MEDIUM HYBRID | D13: =_xlfn.XLOOKUP(A13,Sheet1!A:A,Sheet1!C:C,"") -> 2899 | E13: 2899 | F13: TEMPURPEDIC | H13: .The removable, machine-washable, and cool-to-the-touch SmartClimate cover features heat-absorbing fibers, drawing heat away from the body for added cooling comfort..Specially ventilated TEMPUR-Material delivers additional airflow and breathability, while providing pressure relief and motion absorption..Advanced Relief Material is the most pressure-relieving material made by Tempur-Pedic and contours to your body for ultimate comfort. .Hybrid technology mixes premium innersprings with one-of-a-kind Tempur-Pedic materials to deliver the right combination of relief and support. | I13: Adult | J13: Twin XL | K13: Hybrid | L13: 4-Premier | M13: Side/Back/Stomach | N13: 5-Ultimate | O13: 4-Premier | P13: Medium
A14: 50007561 | B14: =_xlfn.XLOOKUP(A14,Sheet1!A:A,Sheet1!D:D,"") -> LUXEADAPT 2.0 SOFT | C14: TWXL LUXEADAPT SOFT | D14: =_xlfn.XLOOKUP(A14,Sheet1!A:A,Sheet1!C:C,"") -> 4199 | E14: 4199 | F14: TEMPURPEDIC | H14: .The removable, machine-washable, and cool-to-the-touch SmartClimate cover features heat-absorbing fibers, drawing heat away from the body for added cooling comfort..Specially ventilated TEMPUR-Material delivers additional airflow and breathability, while providing pressure relief and motion absorption..Advanced Relief Material is the most pressure-relieving material made by Tempur-Pedic and contours to your body for ultimate comfort. .An ergonomic 5-zone support layer conforms to your body for targeted support in the spine, hips, and shoulders for personalized comfort. | I14: Adult | J14: Twin XL | K14: Foam | L14: 5-Ultimate | M14: Side/Back | N14: 5-Ultimate | O14: 4-Premier | P14: Soft
A15: 50007585 | B15: =_xlfn.XLOOKUP(A15,Sheet1!A:A,Sheet1!D:D,"") -> LUXEADAPT 2.0 MEDIUM HYBRID | C15: TWXL LUXEADAPT MEDIUM HYBRID | D15: =_xlfn.XLOOKUP(A15,Sheet1!A:A,Sheet1!C:C,"") -> 4199 | E15: 4199 | F15: TEMPURPEDIC | H15: .The removable, machine-washable, and cool-to-the-touch SmartClimate cover features heat-absorbing fibers, drawing heat away from the body for added cooling comfort..Specially ventilated TEMPUR-Material delivers additional airflow and breathability, while providing pressure relief and motion absorption..Advanced Relief Material is the most pressure-relieving material made by Tempur-Pedic and contours to your body for ultimate comfort. .Hybrid technology mixes premium innersprings with a proprietary hybrid material to deliver a lighter, more-responsive feel that helps support any sleep position. | I15: Adult | J15: Twin XL | K15: Hybrid | L15: 5-Ultimate | M15: Side/Back/Stomach | N15: 5-Ultimate | O15: 4-Premier | P15: Medium
A16: 50007624 | B16: =_xlfn.XLOOKUP(A16,Sheet1!A:A,Sheet1!D:D,"") -> LUXEBREEZE 2.0 FIRM | C16: TWXL LUXEBREEZE FIRM | D16: =_xlfn.XLOOKUP(A16,Sheet1!A:A,Sheet1!C:C,"") -> 5199 | E16: 5199 | F16: TEMPURPEDIC | H16: The all-new TEMPUR-LuxeBreeze mattress feels up to 10 cooler. Features advanced Pure Cool Plus material designed to pull heat away from the body so even the hottest sleepers can stay cool throughout the night. One-of-a-kind Tempur-Pedic Ventilated Advanced Relief material increases airflow throughout the mattress for a deeper, more restful sleep. | I16: Adult | J16: Twin XL | K16: Foam | L16: 5-Ultimate | M16: Stomach/Back | N16: 5-Ultimate | O16: 5-Ultimate | P16: Firm
A17: 50009870 | B17: =_xlfn.XLOOKUP(A17,Sheet1!A:A,Sheet1!D:D,"") -> TUFT & NEEDLE STITCH TN3.1 | C17: TWX T&N TN3.1 | D17: =_xlfn.XLOOKUP(A17,Sheet1!A:A,Sheet1!C:C,"") -> 797 | E17: 999 | F17: TUFT & NEEDLE | G17: P | I17: Adult | J17: Twin XL | K17: Hybrid | L17: 3-Superior | M17: Side/Back/Stomach | N17: 3-Superior | O17: 3-Superior | P17: Medium
A18: 50009882 | B18: =_xlfn.XLOOKUP(A18,Sheet1!A:A,Sheet1!D:D,"") -> TUFT & NEEDLE STITCH TN5.1 | C18: TWX T&N TN5.1 | D18: =_xlfn.XLOOKUP(A18,Sheet1!A:A,Sheet1!C:C,"") -> 795 | E18: 1399 | F18: TUFT & NEEDLE | G18: P | I18: Adult | J18: Twin XL | K18: Hybrid | L18: 4-Premier | M18: Stomach/Back | N18: 4-Premier | O18: 4-Premier | P18: Firm
A19: 50009907 | B19: =_xlfn.XLOOKUP(A19,Sheet1!A:A,Sheet1!D:D,"") -> TUFT & NEEDLE STITCH TN9.1 | C19: TWX T&N TN9.1 | D19: =_xlfn.XLOOKUP(A19,Sheet1!A:A,Sheet1!C:C,"") -> 1597 | E19: 2099 | F19: TUFT & NEEDLE | G19: P | I19: Adult | J19: Twin XL | K19: Hybrid | L19: 5-Ultimate | M19: Side/Back | N19: 4-Premier | O19: 4-Premier | P19: Soft
A20: 50009933 | B20: =_xlfn.XLOOKUP(A20,Sheet1!A:A,Sheet1!D:D,"") -> TUFT & NEEDLE TN1 | C20: TWX T&N TN1 | D20: =_xlfn.XLOOKUP(A20,Sheet1!A:A,Sheet1!C:C,"") -> 577 | E20: 699 | F20: TUFT & NEEDLE | G20: P | H20: Reclaim your nights and wake refreshed for your days with the Tuft & Needle TN1 12 Firm mattress. Available in a standard flat-mattress construction, this mattress offers innovative cooling, responsive pressure relief, and the bounce back support of T&N Adaptive foam, so you can sink deeply into sleep-but never into your mattress. Unlike memory foam, Tuft & Needle's T&N Adaptive foam doesn't sink under your weight. Instead, it keeps you lifted while contouring to relieve pressure where you need it most. Rest easy as this ventilated foam helps channel airflow through the mattress and a breathable cover helps you sleep comfortably. Plus, feel cool as T&N AdaptiveCool gel foam technology, designed to help absorb heat, is ribboned across the center-third of the mattress to promote optimal cooling. With the addition of comfortable support foams, each Tuft & Needle TN1 12 Firm flat-mattress protects your rest so you can wake up refreshed and ready for the day. | I20: Adult | J20: Twin XL | K20: Foam | L20: 2-Good | M20: Stomach/Back | N20: 2-Good | O20: 2-Good | P20: Firm
A21: 50010570 | B21: =_xlfn.XLOOKUP(A21,Sheet1!A:A,Sheet1!D:D,"") -> MOLECULE CORE | C21: TWXL MOLECULE CORE | D21: =_xlfn.XLOOKUP(A21,Sheet1!A:A,Sheet1!C:C,"") -> 447 | E21: 949 | F21: MOLECULE | J21: Twin XL | K21: Foam | L21: 3-Superior | M21: Side/Back/Stomach | N21: 3-Superior | O21: 3-Superior | P21: Medium
A22: 50010671 | B22: =_xlfn.XLOOKUP(A22,Sheet1!A:A,Sheet1!D:D,"") -> BROAD PEAK MEDIUM HYBRID | C22: TWXL BROAD PEAK | D22: =_xlfn.XLOOKUP(A22,Sheet1!A:A,Sheet1!C:C,"") -> 695 | E22: 849.99 | F22: BEAUTYREST SELECT | G22: P | H22: Developed by the pioneer of the hybrid mattress, the new Beautyrest Select Hybrid line offers consistent that conforms to your body, allowing you to find your optimal sleep position. The superior stretch and recovery surface adapts with you throughout the night, enabling you to engage more closely with the pressure relieving memory foams for a deep, easy sleep. This unique construction enhances the benefits of both our Pocketed Coil Technology and gel memory foams to provide comfort and breathability. | I22: Adult | J22: Twin XL | K22: Hybrid | L22: 3-Superior | M22: Side/Back/Stomach | N22: 3-Superior | O22: 3-Superior | P22: Medium
A23: 50011053 | B23: =_xlfn.XLOOKUP(A23,Sheet1!A:A,Sheet1!D:D,"") -> BAY DREAMER | C23: TWX BAY DREAMER | D23: =_xlfn.XLOOKUP(A23,Sheet1!A:A,Sheet1!C:C,"") -> 445 | E23: 549.99 | F23: TOMMY BAHAMA | G23: P | I23: Kid | J23: Twin XL | K23: Innerspring | L23: 2-Good | M23: Side/Back | N23: 4-Premier | O23: 2-Good | P23: Soft
A24: 50011065 | B24: =_xlfn.XLOOKUP(A24,Sheet1!A:A,Sheet1!D:D,"") -> MAKE WAVES | C24: TWX MAKE WAVES | D24: =_xlfn.XLOOKUP(A24,Sheet1!A:A,Sheet1!C:C,"") -> 495 | E24: 599.99 | F24: TOMMY BAHAMA | G24: P | I24: Kid | J24: Twin XL | K24: Hybrid | L24: 2-Good | M24: Stomach/Back | N24: 4-Premier | O24: 2-Good | P24: Firm
A25: 50011077 | B25: =_xlfn.XLOOKUP(A25,Sheet1!A:A,Sheet1!D:D,"") -> SEASIDE SERENITY | C25: TWX SEASIDE SERENITY | D25: =_xlfn.XLOOKUP(A25,Sheet1!A:A,Sheet1!C:C,"") -> 595 | E25: 699.99 | F25: TOMMY BAHAMA | G25: P | I25: Kid | J25: Twin XL | K25: Innerspring | L25: 2-Good | M25: Side/Back/Stomach | N25: 4-Premier | O25: 2-Good | P25: Medium
A26: 50011344 | B26: =_xlfn.XLOOKUP(A26,Sheet1!A:A,Sheet1!D:D,"") -> FORESTER | C26: TWX FORESTER | D26: =_xlfn.XLOOKUP(A26,Sheet1!A:A,Sheet1!C:C,"") -> 647 | E26: 849.99 | F26: THERAPEDIC | G26: P | I26: Adult | J26: Twin XL | K26: Innerspring | L26: 2-Good | M26: Stomach/Back | N26: 3-Superior | O26: 2-Good | P26: Extra Firm
A27: 50011368 | B27: =_xlfn.XLOOKUP(A27,Sheet1!A:A,Sheet1!D:D,"") -> DARLINGTON | C27: TWX DARLINGTON | D27: =_xlfn.XLOOKUP(A27,Sheet1!A:A,Sheet1!C:C,"") -> 547 | E27: 649.99 | F27: THERAPEDIC | G27: P | I27: Adult | J27: Twin XL | K27: Innerspring | L27: 2-Good | M27: Side/Back/Stomach | N27: 2-Good | O27: 3-Superior | P27: Medium
A28: 50011382 | B28: =_xlfn.XLOOKUP(A28,Sheet1!A:A,Sheet1!D:D,"") -> HASTINGS | C28: TWXL HASTINGS | D28: =_xlfn.XLOOKUP(A28,Sheet1!A:A,Sheet1!C:C,"") -> 627 | E28: 949.99 | F28: THERAPEDIC HYBRID | G28: P | J28: Twin XL | K28: Hybrid | L28: 2-Good | M28: Side/Back | N28: 3-Superior | O28: 3-Superior | P28: Soft
A29: 50011457 | B29: =_xlfn.XLOOKUP(A29,Sheet1!A:A,Sheet1!D:D,"") -> KAANAPALI | C29: TWXL KAANAPALI | D29: =_xlfn.XLOOKUP(A29,Sheet1!A:A,Sheet1!C:C,"") -> 1249.99 | E29: 1249.99 | F29: THERAPEDIC HYBRID | G29: P | I29: Adult | J29: Twin XL | K29: Hybrid | L29: 3-Superior | M29: Stomach/Back | N29: 4-Premier | O29: 3-Superior | P29: Firm
A30: 50011495 | B30: =_xlfn.XLOOKUP(A30,Sheet1!A:A,Sheet1!D:D,"") -> LEDO | C30: TWXL LEDO | D30: =_xlfn.XLOOKUP(A30,Sheet1!A:A,Sheet1!C:C,"") -> 1449.99 | E30: 1449.99 | F30: THERAPEDIC HYBRID | G30: P | I30: Adult | J30: Twin XL | K30: Hybrid | L30: 4-Premier | M30: Side/Back/Stomach | N30: 4-Premier | O30: 3-Superior | P30: Medium
A31: 50020862 | B31: =_xlfn.XLOOKUP(A31,Sheet1!A:A,Sheet1!D:D,"") -> CAPERTEE | C31: TWXL CAPERTEE | D31: =_xlfn.XLOOKUP(A31,Sheet1!A:A,Sheet1!C:C,"") -> 797 | E31: 1099.99 | F31: DREW & JONATHAN | G31: P | I31: Adult | J31: Twin XL | K31: Innerspring | L31: 3-Superior | M31: Side/Back/Stomach | N31: 3-Superior | O31: 3-Superior | P31: Medium
A32: 50020925 | B32: =_xlfn.XLOOKUP(A32,Sheet1!A:A,Sheet1!D:D,"") -> ARADA CANYON | C32: TWXL ARADA CANYON | D32: =_xlfn.XLOOKUP(A32,Sheet1!A:A,Sheet1!C:C,"") -> 1297 | E32: 1599.99 | F32: DREW & JONATHAN | G32: P | I32: Adult | J32: Twin XL | K32: Innerspring | L32: 4-Premier | M32: Side/Back | N32: 3-Superior | O32: 3-Superior | P32: Soft
A33: 50022210 | B33: =_xlfn.XLOOKUP(A33,Sheet1!A:A,Sheet1!D:D,"") -> OCEANA MIST | C33: TWX OCEANA MIST | D33: =_xlfn.XLOOKUP(A33,Sheet1!A:A,Sheet1!C:C,"") -> 377 | E33: 679.99 | F33: BEAUTYSLEEP | G33: P | H33: The Beauty Sleep Oceana Mist 11.5 Medium Hybrid mattress is designed for your lifestyle. With a smooth top panel, the Beauty Sleep Oceana Mist 11.5 Medium Hybrid mattress features AllCool Gel Foam and AllCool Gel Memory Foam that contours to your body for the ultimate pressure relief. Premium foams provide a responsive sleep surface for all-night comfort, support, airflow, and breathability. Plus, firm 815 Original Beauty Sleep Pocketed Coils provide consistent, supportive sleep at a value designed for your lifestyle. Medium Smooth Top Hybrid mattress. | I33: Adult | J33: Twin XL | K33: Hybrid | L33: 2-Good | M33: Side/Back/Stomach | N33: 3-Superior | O33: 2-Good | P33: Medium
A34: 50025747 | B34: =_xlfn.XLOOKUP(A34,Sheet1!A:A,Sheet1!D:D,"") -> LEVEL THREE PLUSH | C34: TWXL WORLD CLASS LEVEL THREE PLUSH | D34: =_xlfn.XLOOKUP(A34,Sheet1!A:A,Sheet1!C:C,"") -> 1329 | E34: 1329 | F34: BEAUTYREST WORLD CLASS | H34: Step up to a world class sleep experience with Beautyrest World Class. Provides cushy comfort that responds to movement with a soft-yet-supportive feel. InfiniCool MAX Technology adds advanced cooling with vertical cooling fibers. SurfaceTouch Gel Memory Foam is quilted into the sleep surface to unlock immediate, advanced comfort. World Class Relief HD Foam, featured in all level three Beautyrest mattresses, adapts to body temperature, providing responsive pressure relief. Beautyrest ActiveResponse MAX HD Memory Foam creates high-density contouring to help alleviate aches and pains. 1000-density Pocketed Coil Technology and higher density foams offer individualized support motion separation. | I34: Adult | J34: Twin XL | K34: Innerspring | L34: 4-Premier | M34: Side/Back | N34: 4-Premier | O34: 4-Premier | P34: Soft
A35: 50025759 | B35: =_xlfn.XLOOKUP(A35,Sheet1!A:A,Sheet1!D:D,"") -> LEVEL THREE MEDIUM PILLOWTOP | C35: TWXL WORLD CLASS LEVEL THREE MED PT | D35: =_xlfn.XLOOKUP(A35,Sheet1!A:A,Sheet1!C:C,"") -> 1529 | E35: 1529 | F35: BEAUTYREST WORLD CLASS | H35: Step up to a world class sleep experience with Beautyrest World Class. Provides medium support with just the right amount of pressure relief and cloud-like top layer. InfiniCool MAX Technology adds advanced cooling combined with natural lux fibers for added surface breathability. SurfaceTouch Gel Memory Foam is quilted into the sleep surface to unlock immediate, advanced comfort. GelTouch Foam helps provide comfort, support, airflow and breathability. World Class Relief HD Foam, featured in all level three Beautyrest mattresses, adapts to body temperature, providing responsive pressure relief. Beautyrest ActiveResponse MAX HD Memory Foam creates high-density contouring to help alleviate aches and pains. 1000-density Pocketed Coil Technology and higher density foams offer individualized support motion separation. | I35: Adult | J35: Twin XL | K35: Innerspring | L35: 4-Premier | M35: Side/Back/Stomach | N35: 4-Premier | O35: 4-Premier | P35: Medium
A36: 50025800 | B36: =_xlfn.XLOOKUP(A36,Sheet1!A:A,Sheet1!D:D,"") -> LEVEL FOUR PLUSH PILLOWTOP | C36: TWXL WORLD CLASS LEVEL FOUR PLUSH PT | D36: =_xlfn.XLOOKUP(A36,Sheet1!A:A,Sheet1!C:C,"") -> 1829 | E36: 1829 | F36: BEAUTYREST WORLD CLASS | H36: Step up to a world class sleep experience with Beautyrest World Class. Provides cushy comfort that responds to movement with a soft-yet-supportive feel and a cloud-like top layer. InfiniCool MAX Technology adds advanced cooling with vertical cooling fibers. Level Four mattresses feature twice the SurfaceTouch Gel Memory Foam, unlocking even more pressure relief right at the surface. World Class Relief HD Foam, featured in all level four Beautyrest mattresses, offers remarkable pressure relief that responds to your body. Beautyrest ActiveResponse MAX HD Memory Foam helps alleviate aches and pains withhigh-density contouring. 1000-density Pocketed Coil Technology and higher density foams offer individualized support motion separation. | I36: Adult | J36: Twin XL | K36: Innerspring | L36: 5-Ultimate | M36: Side/Back | N36: 4-Premier | O36: 4-Premier | P36: Soft
A37: 50028957 | B37: =_xlfn.XLOOKUP(A37,Sheet1!A:A,Sheet1!D:D,"") -> KERRY PARK | C37: TWX KERRY PARK | D37: =_xlfn.XLOOKUP(A37,Sheet1!A:A,Sheet1!C:C,"") -> 877 | E37: 1479 | F37: CORRECT COMFORT | G37: P | I37: Adult | J37: Twin XL | K37: Innerspring | L37: 4-Premier | M37: Side/Back | N37: 3-Superior | O37: 3-Superior | P37: Extra Soft
A38: 50028969 | B38: =_xlfn.XLOOKUP(A38,Sheet1!A:A,Sheet1!D:D,"") -> BRADFORD HILL | C38: TWX BRADFORD HILL | D38: =_xlfn.XLOOKUP(A38,Sheet1!A:A,Sheet1!C:C,"") -> 645 | E38: 749 | F38: CORRECT COMFORT | G38: P | I38: Adult | J38: Twin XL | K38: Foam | L38: 3-Superior | M38: Side/Back/Stomach | N38: 3-Superior | O38: 2-Good | P38: Medium
A39: 50028971 | B39: =_xlfn.XLOOKUP(A39,Sheet1!A:A,Sheet1!D:D,"") -> NORTHGATE | C39: TWX NORTHGATE | D39: =_xlfn.XLOOKUP(A39,Sheet1!A:A,Sheet1!C:C,"") -> 977 | E39: 1779 | F39: CORRECT COMFORT | G39: P | J39: Twin XL | K39: Foam | L39: 4-Premier | M39: Side/Back/Stomach | N39: 3-Superior | O39: 3-Superior | P39: Medium
A40: 50029175 | B40: =_xlfn.XLOOKUP(A40,Sheet1!A:A,Sheet1!D:D,"") -> BRIERWOOD | C40: TWXL BRIERWOOD | D40: =_xlfn.XLOOKUP(A40,Sheet1!A:A,Sheet1!C:C,"") -> 597 | E40: 719 | F40: POSTUREPEDIC | G40: P | H40: The Sealy Posturepedic Briarwood Medium mattress offers lasting comfort and superior support to help maintain natural body alignment and reduce nagging Bed Aches. The orthopedic-inspired Posturepedic Support System features exclusive PrecisionFit Coils, arranged right where you need them. Plus the Coil Edge provides a solid surface that's built to last. | I40: Adult | J40: Twin XL | K40: Innerspring | L40: 2-Good | M40: Side/Back/Stomach | N40: 2-Good | O40: 2-Good | P40: Medium
...

Sheet Sheet1
A1: SKU | B1: Customer Description | C1: Zone 0 Price | D1: Theme
A2: 50000543 | B2: TWX CASPER CLOUD ONE | C2: 879 | D2: CASPER CLOUD ONE
A3: 50000555 | B3: TWXL CASPER ONE | C3: 679 | D3: CASPER ONE
A4: 50000567 | B4: TWXL CASPER DREAM | C4: 1275 | D4: CASPER DREAM
A5: 50000579 | B5: TWXL CASPER SNOW 2.0 | C5: 1595 | D5: CASPER SNOW 2.0
A6: 50000581 | B6: TWXL CASPER SNOW MAX | C6: 2595 | D6: CASPER SNOW MAX
A7: 50000593 | B7: TWXL CASPER DREAM MAX | C7: 2075 | D7: CASPER DREAM MAX
A8: 50000682 | B8: TWXL CASPER ONYX 2.0 | C8: 699 | D8: CASPER ONYX 2.0
A9: 50001773 | B9: TWX SMART MATCH 2.0 | C9: 1077 | D9: SMART MATCH 2.0
A10: 50004111 | B10: 8 INCH FUTON MATTRES | C10: 199.99 | D10: FUTON
A11: 50006141 | B11: ASTRO KIDS PILLOW W/PILLOW CASE | C11: 55.99 | D11: ASTRO PILLOW
A12: 50007460 | B12: TWXL ADAPT MEDIUM | C12: 1699 | D12: ADAPT 2.0 MEDIUM
A13: 50007472 | B13: TWXL ADAPT MEDIUM HYBRID | C13: 1999 | D13: ADAPT 2.0 MEDIUM HYBRID
... A210: 50212112 | B210: TW HI PRO FOUNDATION | C210: 200 | D210: BOX SPRING
A211: 50214659 | B211: CHOOSE YOUR FOUNDATION | D211: BOX SPRING
A212: 50214762 | B212: TW HI PRO FOUNDATION | C212: 200 | D212: BOX SPRING
A213: 50215601 | B213: TW HI PRO FOUNDATION | C213: 200 | D213: BOX SPRING
A214: 50216184 | B214: TW HI PRO FOUNDATION | C214: 200 | D214: BOX SPRING
A215: 50218607 | B215: TW EASE 4.0 | C215: 899 | D215: EASE 4.0
A216: 50219952 | B216: CHOOSE YOUR FOUNDATION | D216: BOX SPRING
A217: 50221705 | B217: CHOOSE YOUR FOUNDATION | D217: BOX SPRING
A218: 50222264 | B218: TW HI PRO FOUNDATION | C218: 200 | D218: BOX SPRING
A219: 50222606 | B219: TWIN BUNKIE BOARD | C219: 69.99 | D219: BUNKIE BOARD
A220: 50222620 | B220: TW ULTRA LO 3 FOUNDATION | C220: 200 | D220: BOX SPRING
A221: 50229270 | B221: TW HI PRO FOUNDATION | C221: 200 | D221: BOX SPRING
A222: 50248509 | B222: TW S&F HI PRO FOUNDATION | C222: 240 | D222: BOX SPRING
A223: 50252635 | B223: TW HI PRO FOUNDATION | C223: 200 | D223: BOX SPRING
A224: 50283476 | B224: TWIN HI PRO FOUNDATION | C224: 200 | D224: BOX SPRING
A225: 50299049 | B225: CHOOSE YOUR FOUNDATION | D225: BOX SPRING
A226: 50299140 | B226: CHOOSE YOUR FOUNDATION | D226: BOX SPRING
A227: 50299277 | B227: CHOOSE YOUR FOUNDATION | D227: BOX SPRING
A228: 50299758 | B228: TW EZ-LIFT FOUNDATION | C228: 200 | D228: EZ-LIFT FOUNDATION
A229: 50300549 | B229: FL CASPER CLOUD ONE | C229: 959 | D229: CASPER CLOUD ONE
A230: 50300551 | B230: FL CASPER ONE | C230: 759 | D230: CASPER ONE
A231: 50300563 | B231: FL CASPER DREAM | C231: 1395 | D231: CASPER DREAM
A232: 50300575 | B232: FL CASPER SNOW 2.0 | C232: 1995 | D232: CASPER SNOW 2.0
A233: 50300587 | B233: FL CASPER SNOW MAX | C233: 2995 | D233: CASPER SNOW MAX
A234: 50300599 | B234: FL CASPER DREAM MAX | C234: 2475 | D234: CASPER DREAM MAX
A235: 50300688 | B235: FL CASPER ONYX 2.0 | C235: 749 | D235: CASPER ONYX 2.0
A236: 50301779 | B236: FL SMART MATCH 2.0 | C236: 1177 | D236: SMART MATCH 2.0
...
